#VRML_SIM R2025a utf8

EXTERNPROTO "https://raw.githubusercontent.com/cyberbotics/webots/R2025a/projects/objects/backgrounds/protos/TexturedBackground.proto"
EXTERNPROTO "https://raw.githubusercontent.com/cyberbotics/webots/R2025a/projects/objects/backgrounds/protos/TexturedBackgroundLight.proto"
EXTERNPROTO "https://raw.githubusercontent.com/cyberbotics/webots/R2025a/projects/objects/floors/protos/RectangleArena.proto"

WorldInfo {
  contactProperties [
    DEF frictionless ContactProperties {
      material2 "frictionless"
      coulombFriction [
        0
      ]
    }
    ContactProperties {
    }
  ]
}
Viewpoint {
  orientation 0.17004966746180647 0.0012947628706238925 -0.9854346422697134 3.2383609267516507
  position 0.7438204145235195 -0.0627133967695829 0.3543113313744862
}
TexturedBackground {
}
TexturedBackgroundLight {
}
RectangleArena {
}
Robot {
  translation 0 -5.76884e-10 0.1
  children [
    DEF Base_link Pose {
      children [
        DEF L_led_pose Pose {
          translation -0.0425 0.04005 0
          rotation 0 0 1 1.57079632679
          children [
            Shape {
              appearance PBRAppearance {
              }
              geometry Box {
                size 0.01 0.002 0.005
              }
            }
            DEF ds_left DistanceSensor {
              rotation 0 0 1 1.57079632679
              name "ds_left"
            }
          ]
        }
        DEF LF_led_pose Pose {
          translation -0.030052 0.070552 0
          rotation 0 0 1 0.785398
          children [
            Shape {
              appearance PBRAppearance {
              }
              geometry Box {
                size 0.01 0.002 0.005
              }
            }
            DEF ds_left_front DistanceSensor {
              rotation 0 0 1 1.57079632679
              name "ds_left_front"
            }
          ]
        }
        DEF F_led_pose Pose {
          translation 0 0.083 0
          children [
            Shape {
              appearance PBRAppearance {
              }
              geometry Box {
                size 0.01 0.002 0.005
              }
            }
            DEF ds_front DistanceSensor {
              rotation 0 0 1 1.57079632679
              name "ds_front"
            }
          ]
        }
        DEF RF_led_pose Pose {
          translation 0.030052 0.070552 0
          rotation 0 0 1 -0.785398
          children [
            Shape {
              appearance PBRAppearance {
              }
              geometry Box {
                size 0.01 0.002 0.005
              }
            }
            DEF ds_right_front DistanceSensor {
              rotation 0 0 1 1.57079632679
              name "ds_right_front"
            }
          ]
        }
        DEF R_led_pose Pose {
          translation 0.0425 0.04005 0
          rotation 0 0 1 -1.57079632679
          children [
            Shape {
              appearance PBRAppearance {
              }
              geometry Box {
                size 0.01 0.002 0.005
              }
            }
            DEF ds_right DistanceSensor {
              rotation 0 0 1 1.57079632679
              name "ds_right"
            }
          ]
        }
        DEF caster_pose Pose {
          translation 0 0.06 0
          children [
            Solid {
              children [
                Shape {
                  appearance PBRAppearance {
                  }
                  geometry Capsule {
                    height 0.01
                    radius 0.005
                  }
                }
              ]
              name "solid(2)"
              contactMaterial "frictionless"
              boundingObject Capsule {
                height 0.01
                radius 0.005
                subdivision 16
              }
              physics Physics {
              }
            }
          ]
        }
        DEF R_motor_pose Pose {
          translation 0.04 0 0
          children [
            HingeJoint {
              jointParameters HingeJointParameters {
                axis -1 0 0
              }
              device [
                PositionSensor {
                  name "r_encoder"
                }
                RotationalMotor {
                  name "r_motor"
                  maxTorque 0.1
                }
              ]
              endPoint Solid {
                rotation 9.218572170393463e-11 1 9.218540768544289e-11 1.5707963267899905
                children [
                  Shape {
                    appearance PBRAppearance {
                    }
                    geometry Cylinder {
                      height 0.01
                      radius 0.01
                    }
                  }
                ]
                name "solid(1)"
                boundingObject Cylinder {
                  height 0.01
                  radius 0.01
                }
                physics Physics {
                  mass 0.01
                }
              }
            }
          ]
        }
        DEF L_motor_pose Pose {
          translation -0.04 0 0
          children [
            HingeJoint {
              jointParameters HingeJointParameters {
                axis -1 0 0
              }
              device [
                PositionSensor {
                  name "l_encoder"
                }
                RotationalMotor {
                  name "l_motor"
                  maxTorque 0.1
                }
              ]
              endPoint Solid {
                rotation -1.2927090912979041e-09 1 -1.292707992233183e-09 1.5707963267899925
                children [
                  Shape {
                    appearance PBRAppearance {
                    }
                    geometry Cylinder {
                      height 0.01
                      radius 0.01
                    }
                  }
                ]
                boundingObject Cylinder {
                  height 0.01
                  radius 0.01
                }
                physics Physics {
                  mass 0.01
                }
              }
            }
          ]
        }
        CadShape {
          url [
            "../models/mms-chassies.dae"
          ]
        }
      ]
    }
  ]
  boundingObject Group {
    children [
      Pose {
        translation 0 0.04 0.001
        children [
          Cylinder {
            height 0.002
            radius 0.0425
          }
        ]
      }
      Pose {
        translation 0 0.01025 0.001
        children [
          Shape {
            geometry Box {
              size 0.085 0.061 0.002
            }
          }
        ]
      }
    ]
  }
  physics Physics {
    mass 0.3
  }
  controller "<extern>"
}
